getting original df
ERROR: HTTP response was bad
https://picsure.biodatacatalyst.nhlbi.nih.gov/picsure/query/sync
{'server': 'awselb/2.0', 'date': 'Mon, 02 Mar 2020 17:58:04 GMT', 'content-type': 'text/html', 'content-length': '148', 'connection': 'keep-alive', 'status': '504'}
<html>
<head><title>504 Gateway Time-out</title></head>
<body bgcolor="white">
<center><h1>504 Gateway Time-out</h1></center>
</body>
</html>

Traceback (most recent call last):
  File "studies_stats.py", line 36, in <module>
    original_df = get_one_study(resource, phs, studies_info, variablesDict, low_memory=False)
  File "/home/ubuntu/git_repos/PheWAS/python/python_lib/utils.py", line 12, in wrapper_timer
    output = function(*args, **kwargs)
  File "/home/ubuntu/git_repos/PheWAS/python/python_lib/utils.py", line 107, in get_one_study
    **kwargs)
  File "/home/ubuntu/git_repos/PheWAS/python/python_lib/wrappers.py", line 73, in query_runner
    return _run_query(query, result_type, **kwargs)
  File "/home/ubuntu/git_repos/PheWAS/python/python_lib/wrappers.py", line 61, in _run_query
    return query.getResultsDataFrame(**kwargs)
  File "/home/ubuntu/miniconda3/envs/PheWAS_env/lib/python3.6/site-packages/PicSureHpdsLib/PicSureHpdsQuery.py", line 236, in getResultsDataFrame
    if result.error == True:
AttributeError: 'dict' object has no attribute 'error'
