getting original df
Traceback (most recent call last):
  File "studies_stats.py", line 36, in <module>
    original_df = get_one_study(resource, phs, studies_info, variablesDict, low_memory=False)
  File "/home/ubuntu/git_repos/PheWAS/python/python_lib/utils.py", line 12, in wrapper_timer
    output = function(*args, **kwargs)
  File "/home/ubuntu/git_repos/PheWAS/python/python_lib/utils.py", line 102, in get_one_study
    selected_var = variablesDict.loc[study_name, "varName"].values.tolist()
  File "/home/ubuntu/miniconda3/envs/PheWAS_env/lib/python3.6/site-packages/pandas/core/indexing.py", line 1761, in __getitem__
    return self._getitem_tuple(key)
  File "/home/ubuntu/miniconda3/envs/PheWAS_env/lib/python3.6/site-packages/pandas/core/indexing.py", line 1271, in _getitem_tuple
    return self._getitem_lowerdim(tup)
  File "/home/ubuntu/miniconda3/envs/PheWAS_env/lib/python3.6/site-packages/pandas/core/indexing.py", line 1388, in _getitem_lowerdim
    section = self._getitem_axis(key, axis=i)
  File "/home/ubuntu/miniconda3/envs/PheWAS_env/lib/python3.6/site-packages/pandas/core/indexing.py", line 1964, in _getitem_axis
    return self._get_label(key, axis=axis)
  File "/home/ubuntu/miniconda3/envs/PheWAS_env/lib/python3.6/site-packages/pandas/core/indexing.py", line 624, in _get_label
    return self.obj._xs(label, axis=axis)
  File "/home/ubuntu/miniconda3/envs/PheWAS_env/lib/python3.6/site-packages/pandas/core/generic.py", line 3535, in xs
    loc, new_index = self.index.get_loc_level(key, drop_level=drop_level)
  File "/home/ubuntu/miniconda3/envs/PheWAS_env/lib/python3.6/site-packages/pandas/core/indexes/multi.py", line 2846, in get_loc_level
    indexer = self._get_level_indexer(key, level=level)
  File "/home/ubuntu/miniconda3/envs/PheWAS_env/lib/python3.6/site-packages/pandas/core/indexes/multi.py", line 2943, in _get_level_indexer
    raise KeyError(key)
KeyError: nan
